Workbook
Name _a0csXCPXx1W: Metadata!$C$359
Name _a0Tb0vzKk1m: Metadata!$C$1087
Name _a2xwzp8oVHw: Metadata!$C$589
Name _A3k9S8n5UDB: Metadata!$C$840
Name _A5bhyAmcZKV: Metadata!$C$555
Name _a5ii3ZTvZJl: Metadata!$C$62
Name _A7vlGlMOCQi: Metadata!$C$606
Name _a7y6M6RSlfA: Metadata!$C$472
Name _A8qvwcGQ7oR: Metadata!$C$379
Name _A8ZYkf5BTQ1: Metadata!$C$614
Name _abfQV1VOf3t: Metadata!$C$225
Name _aBKbsKeMhM6: Metadata!$C$78
Name _abpFZulJ2EI: Metadata!$C$895
Name _ABy98AXLIvi: Metadata!$C$451
Name _ac1IouPLQqe: Metadata!$C$565
Name _ACalScnrl2I: Metadata!$C$1168
Name _acxdJCjXxeg: Metadata!$C$859
Name _ADfCJWnnU2O: Metadata!$C$597
Name _aDt6BJ6G5Vh: Metadata!$C$935
Name _Adzexk8xbzD: Metadata!$C$1303
Name _ae8CH5krsam: Metadata!$C$201
Name _aeEH9WsPkWk: Metadata!$C$786
Name _AFIorEPU00q: Metadata!$C$1089
Name _ag1Rvst0gJY: Metadata!$C$920
Name _Agh3IhNPIxF: Metadata!$C$582
Name _AgjjsN3UJiv: Metadata!$C$970
Name _AGWxyqGhgfk: Metadata!$C$607
Name _ahER1ix3fxr: Metadata!$C$74
Name _AifBdH1NgTt: Metadata!$C$955
Name _AJBfDthkySs: Metadata!$C$1078
Name _AjeCGGb8H76: Metadata!$C$1072
Name _Ajnw1b8m6eL: Metadata!$C$1181
Name _Ak4QGxirDXg: Metadata!$C$764
Name _aLiNAjoAsDt: Metadata!$C$679
Name _AlxUCNc8gwW: Metadata!$C$326
Name _amPTixaGdsP: Metadata!$C$915
Name _ANELZaDsI6L: Metadata!$C$754
Name _aNIrqpwcKXv: Metadata!$C$1282
Name _AO3H3mBW9zD: Metadata!$C$899
Name _aoq4jeGV5NM: Metadata!$C$640
Name _aotiqu4EAWq: Metadata!$C$203
Name _aOYOo12rVAs: Metadata!$C$289
Name _apVWLKfARpb: Metadata!$C$1144
Name _aqX2gD5zuya: Metadata!$C$944
Name _arZWO8Ag3iO: Metadata!$C$484
Name _atZNVujwdt4: Metadata!$C$502
Name _AtZVwbugSqv: Metadata!$C$387
Name _aujJ0EVKWer: Metadata!$C$980
Name _aurZ2kUa2St: Metadata!$C$149
Name _AUStREIxT4s: Metadata!$C$1142
Name _av3fkpFxEXj: Metadata!$C$1294
Name _aVL32L9ycAJ: Metadata!$C$488
Name _AVOrdyQXSal: Metadata!$C$193
Name _AYWCbVecRKQ: Metadata!$C$1289
Name _aZ7Bm5L90rn: Metadata!$C$1232
Name _AZCkBzUZgTr: Metadata!$C$427
Name _AZdPnw0b1lm: Metadata!$C$1047
Name _aZKKBa26tmF: Metadata!$C$294
Name _B3fcwYE45w6: Metadata!$C$779
Name _B4iWc3gcDcn: Metadata!$C$1191

Sheet Demographic
A1: NHWA_MODULE_1_v2 | B1: NATIONAL HEALTH WORKFORCE ACCOUNTS DATA | Y1: Name | Z1: Uid | AA1: ISO | AB1: Regional
B2: Active Health Workforce Demographic Details | W2: =VLOOKUP(W1,Y2:AB264,2,0) -> #N/A | Y2: Afghanistan | Z2: oofyLUJJ6Vy | AA2: AFG | AB2: EMR | AC2: =--ISNUMBER(IFERROR(SEARCH($V$1,Y2,1),"")) -> 1 | AD2: =IF(AC2=1,COUNTIF($AC2:AC$2,1),"") -> 1 | AE2: =IFERROR(INDEX($Y$2:$Y$253,MATCH(ROWS($AD2:AD$2),$AD$2:$AD$253,0)),"") -> Afghanistan
Y3: Albania | Z3: VGOzFKfSazN | AA3: ALB | AB3: EUR | AC3: =--ISNUMBER(IFERROR(SEARCH($V$1,Y3,1),"")) -> 1 | AD3: =IF(AC3=1,COUNTIF($AC3:AC$2,1),"") -> 2 | AE3: =IFERROR(INDEX($Y$2:$Y$253,MATCH(ROWS($AD3:AD$2),$AD$2:$AD$253,0)),"") -> Albania
B4: COUNTRY: | C4: =_HfVjCurKxh2 -> Kenya | F4: REGION: | G4: =IFERROR(VLOOKUP(C4,Y2:AB253,4,0),"") -> AFR | P4: PERIOD: | Q4: 2023 | Y4: Algeria | Z4: mNa42CHbkO7 | AA4: DZA | AB4: AFR | AC4: =--ISNUMBER(IFERROR(SEARCH($V$1,Y4,1),"")) -> 1 | AD4: =IF(AC4=1,COUNTIF($AC4:AC$2,1),"") -> 3 | AE4: =IFERROR(INDEX($Y$2:$Y$253,MATCH(ROWS($AD4:AD$2),$AD$2:$AD$253,0)),"") -> Algeria
Y5: American Samoa | Z5: VYVKdqiXo4b | AA5: ASM | AB5: WPR | AC5: =--ISNUMBER(IFERROR(SEARCH($V$1,Y5,1),"")) -> 1 | AD5: =IF(AC5=1,COUNTIF($AC5:AC$2,1),"") -> 4 | AE5: =IFERROR(INDEX($Y$2:$Y$253,MATCH(ROWS($AD5:AD$2),$AD$2:$AD$253,0)),"") -> American Samoa
B6: SN | C6: Occupation | D6: Total | E6: Activity Level | H6: Gender | J6: Age Group | P6: Place of Birth | R6: Place of Training | U6: Place of Training (foreign trained) | AB6: Andorra | AC6: Rmy6DbwekE1 | AD6: AND | AE6: EUR | AF6: =--ISNUMBER(IFERROR(SEARCH($V$1,AB6,1),"")) -> 1 | AG6: =IF(AF6=1,COUNTIF($AC6:AC$2,1),"") -> 4 | AH6: =IFERROR(INDEX($Y$2:$Y$253,MATCH(ROWS($AD6:AD$2),$AD$2:$AD$253,0)),"") -> Anguilla
E7: Practising | F7: Professionally Active | G7: Licensed to practice | H7: Male | I7: Female | J7: <25 yrs | K7: 25-34 yrs | L7: 35-44 yrs | M7: 45-54 yrs | N7: 55-64 yrs | O7: > 65 yrs | P7: National Born | Q7: Foreign Born | R7: National trained | S7: Foreign Trained | T7: Unknown | U7: National Born | V7: Foreign Born | AB7: Angola | AC7: jFOZHDZpjPL | AD7: AGO | AE7: AFR | AF7: =--ISNUMBER(IFERROR(SEARCH($V$1,AB7,1),"")) -> 1 | AG7: =IF(AF7=1,COUNTIF($AC7:AC$2,1),"") -> 4 | AH7: =IFERROR(INDEX($Y$2:$Y$253,MATCH(ROWS($AD7:AD$2),$AD$2:$AD$253,0)),"") -> Antigua and Barbuda
B8: 1 | C8: Medical Doctors | D8: =IF(COUNT(D9,D10,D17)>0,SUM(D9,D10,D17),NA()) -> 4667 | E8: =IF(COUNT(E9,E10,E17)>0,SUM(E9,E10,E17),NA()) -> #N/A | F8: =IF(COUNT(F9,F10,F17)>0,SUM(F9,F10,F17),NA()) -> #N/A | G8: =IF(COUNT(G9,G10,G17)>0,SUM(G9,G10,G17),NA()) -> #N/A | H8: =IF(COUNT(H9,H10,H17)>0,SUM(H9,H10,H17),NA()) -> 2232 | I8: =IF(COUNT(I9,I10,I17)>0,SUM(I9,I10,I17),NA()) -> 1758 | J8: =IF(COUNT(J9,J10,J17)>0,SUM(J9,J10,J17),NA()) -> 34 | K8: =IF(COUNT(K9,K10,K17)>0,SUM(K9,K10,K17),NA()) -> 1226 | ... V8: =IF(COUNT(V9,V10,V17)>0,SUM(V9,V10,V17),NA()) -> #N/A | Y8: Anguilla | Z8: f4ZFD2aswys | AA8: AIA | AB8: AMR | AC8: =--ISNUMBER(IFERROR(SEARCH($V$1,Y8,1),"")) -> 1 | AD8: =IF(AC8=1,COUNTIF($AC8:AC$2,1),"") -> 5 | AE8: =IFERROR(INDEX($Y$2:$Y$253,MATCH(ROWS($AD8:AD$2),$AD$2:$AD$253,0)),"") -> Argentina
B9: 1.1 | C9: General Medical Practitioners (incl. Family medical practitioners) | D9: 3015 | H9: 2232 | I9: 1758 | J9: 23 | K9: 1176 | L9: 1319 | M9: 321 | N9: 114 | O9: 91 | Q9: 159 | Y9: Antigua and Barbuda | Z9: pfhvgmllA9M | AA9: ATG | AB9: AMR | AC9: =--ISNUMBER(IFERROR(SEARCH($V$1,Y9,1),"")) -> 1 | AD9: =IF(AC9=1,COUNTIF($AC9:AC$2,1),"") -> 6 | AE9: =IFERROR(INDEX($Y$2:$Y$253,MATCH(ROWS($AD9:AD$2),$AD$2:$AD$253,0)),"") -> Armenia
B10: 1.2 | C10: Specialist Medical Practitioners | D10: 1652 | J10: 11 | K10: 50 | L10: 460 | M10: 314 | N10: 138 | O10: 69 | X10: =X11+1 -> 2025 | Y10: Argentina | Z10: AZdPnw0b1lm | AA10: ARG | AB10: AMR | AC10: =--ISNUMBER(IFERROR(SEARCH($V$1,Y10,1),"")) -> 1 | AD10: =IF(AC10=1,COUNTIF($AC10:AC$2,1),"") -> 7 | AE10: =IFERROR(INDEX($Y$2:$Y$253,MATCH(ROWS($AD10:AD$2),$AD$2:$AD$253,0)),"") -> Aruba
B11: 1.2.1 | C11: General paediatricians | D11: 238 | J11: 3 | K11: 31 | L11: 160 | M11: 64 | N11: 11 | O11: 16 | X11: =X12+1 -> 2024 | Y11: Armenia | Z11: cWrL45je7mw | AA11: ARM | AB11: EUR | AC11: =--ISNUMBER(IFERROR(SEARCH($V$1,Y11,1),"")) -> 1 | AD11: =IF(AC11=1,COUNTIF($AC11:AC$2,1),"") -> 8 | AE11: =IFERROR(INDEX($Y$2:$Y$253,MATCH(ROWS($AD11:AD$2),$AD$2:$AD$253,0)),"") -> Australia
B12: 1.2.2 | C12: Obstetricians and Gynaecologists | D12: 296 | J12: 2 | K12: 29 | L12: 138 | M12: 65 | N12: 29 | O12: 25 | X12: =X13+1 -> 2023 | Y12: Aruba | Z12: lKZR6UK0afN | AA12: ABW | AB12: AMR | AC12: =--ISNUMBER(IFERROR(SEARCH($V$1,Y12,1),"")) -> 1 | AD12: =IF(AC12=1,COUNTIF($AC12:AC$2,1),"") -> 9 | AE12: =IFERROR(INDEX($Y$2:$Y$253,MATCH(ROWS($AD12:AD$2),$AD$2:$AD$253,0)),"") -> Austria
B13: 1.2.3 | C13: Psychiatrists Practitioners | X13: =X14+1 -> 2022 | Y13: Australia | Z13: LbWpsX1FJcC | AA13: AUS | AB13: WPR | AC13: =--ISNUMBER(IFERROR(SEARCH($V$1,Y13,1),"")) -> 1 | AD13: =IF(AC13=1,COUNTIF($AC13:AC$2,1),"") -> 10 | AE13: =IFERROR(INDEX($Y$2:$Y$253,MATCH(ROWS($AD13:AD$2),$AD$2:$AD$253,0)),"") -> Azerbaijan
B14: 1.2.4 | C14: Medical group of Specialists Practitioners | D14: 403 | J14: 5 | K14: 12 | L14: 142 | M14: 82 | N14: 40 | O14: 7 | X14: =X15+1 -> 2021 | Y14: Austria | Z14: e9IoKRAkYLO | AA14: AUT | AB14: EUR | AC14: =--ISNUMBER(IFERROR(SEARCH($V$1,Y14,1),"")) -> 1 | AD14: =IF(AC14=1,COUNTIF($AC14:AC$2,1),"") -> 11 | AE14: =IFERROR(INDEX($Y$2:$Y$253,MATCH(ROWS($AD14:AD$2),$AD$2:$AD$253,0)),"") -> Bahamas
B15: 1.2.5 | C15: Surgical group of Specialists Practitioners | D15: 479 | J15: 1 | K15: 86 | L15: 261 | M15: 115 | N15: 50 | O15: 18 | X15: =X16+1 -> 2020 | Y15: Azerbaijan | Z15: ST86paYjRHP | AA15: AZE | AB15: EUR | AC15: =--ISNUMBER(IFERROR(SEARCH($V$1,Y15,1),"")) -> 1 | AD15: =IF(AC15=1,COUNTIF($AC15:AC$2,1),"") -> 12 | AE15: =IFERROR(INDEX($Y$2:$Y$253,MATCH(ROWS($AD15:AD$2),$AD$2:$AD$253,0)),"") -> Bahrain
B16: 1.2.6 | C16: Other Specialists Practitioners | D16: 129 | J16: 2 | K16: 24 | L16: 76 | M16: 24 | N16: 4 | O16: 3 | Q16: 4 | X16: =X17+1 -> 2019 | Y16: Bahamas | Z16: VbbSe7wgS9s | AA16: BHS | AB16: AMR | AC16: =--ISNUMBER(IFERROR(SEARCH($V$1,Y16,1),"")) -> 1 | AD16: =IF(AC16=1,COUNTIF($AC16:AC$2,1),"") -> 13 | AE16: =IFERROR(INDEX($Y$2:$Y$253,MATCH(ROWS($AD16:AD$2),$AD$2:$AD$253,0)),"") -> Bangladesh
B17: 1.3 | C17: Medical doctors not further defined | X17: =X18+1 -> 2018 | Y17: Bahrain | Z17: T7tKHiW1Db1 | AA17: BHR | AB17: EMR | AC17: =--ISNUMBER(IFERROR(SEARCH($V$1,Y17,1),"")) -> 1 | AD17: =IF(AC17=1,COUNTIF($AC17:AC$2,1),"") -> 14 | AE17: =IFERROR(INDEX($Y$2:$Y$253,MATCH(ROWS($AD17:AD$2),$AD$2:$AD$253,0)),"") -> Barbados
B18: 2 | C18: Nursing Personnel | D18: =IF(COUNT(D19,D20,D21)>0,SUM(D19,D20,D21),NA()) -> 34552 | E18: =IF(COUNT(E19,E20,E21)>0,SUM(E19,E20,E21),NA()) -> #N/A | F18: =IF(COUNT(F19,F20,F21)>0,SUM(F19,F20,F21),NA()) -> #N/A | G18: =IF(COUNT(G19,G20,G21)>0,SUM(G19,G20,G21),NA()) -> #N/A | H18: =IF(COUNT(H19,H20,H21)>0,SUM(H19,H20,H21),NA()) -> #N/A | I18: =IF(COUNT(I19,I20,I21)>0,SUM(I19,I20,I21),NA()) -> #N/A | J18: =IF(COUNT(J19,J20,J21)>0,SUM(J19,J20,J21),NA()) -> 688 | K18: =IF(COUNT(K19,K20,K21)>0,SUM(K19,K20,K21),NA()) -> 0 | ... V18: =IF(COUNT(V19,V20,V21)>0,SUM(V19,V20,V21),NA()) -> #N/A | X18: =X19+1 -> 2017 | Y18: Bangladesh | Z18: dNLjKwsVjod | AA18: BGD | AB18: SEAR | AC18: =--ISNUMBER(IFERROR(SEARCH($V$1,Y18,1),"")) -> 1 | AD18: =IF(AC18=1,COUNTIF($AC18:AC$2,1),"") -> 15 | AE18: =IFERROR(INDEX($Y$2:$Y$253,MATCH(ROWS($AD18:AD$2),$AD$2:$AD$253,0)),"") -> Belgium
B19: 2.1 | C19: Nursing Professionals | D19: 33542 | J19: 688 | K19: =[1]Kenya!$J$14 -> 0 | L19: =[1]Kenya!$M$14 -> 0 | M19: =[1]Kenya!$P$14 -> 0 | N19: =[1]Kenya!$S$14 -> 0 | O19: =[1]Kenya!$V$14 -> 0 | X19: =X20+1 -> 2016 | Y19: Barbados | Z19: iNT35p3jsEM | AA19: BRB | AB19: AMR | AC19: =--ISNUMBER(IFERROR(SEARCH($V$1,Y19,1),"")) -> 1 | AD19: =IF(AC19=1,COUNTIF($AC19:AC$2,1),"") -> 16 | AE19: =IFERROR(INDEX($Y$2:$Y$253,MATCH(ROWS($AD19:AD$2),$AD$2:$AD$253,0)),"") -> Benin
B20: 2.2 | C20: Nursing Associate Professionals | D20: 1010 | J20: =[1]Kenya!$G$18 -> 0 | K20: =[1]Kenya!$J$18 -> 0 | L20: =[1]Kenya!$M$18 -> 0 | M20: =[1]Kenya!$P$18 -> 0 | N20: =[1]Kenya!$S$18 -> 0 | O20: 2 | X20: =X21+1 -> 2015 | Y20: Belgium | Z20: KwgjnBBpe5b | AA20: BEL | AB20: EUR | AC20: =--ISNUMBER(IFERROR(SEARCH($V$1,Y20,1),"")) -> 1 | AD20: =IF(AC20=1,COUNTIF($AC20:AC$2,1),"") -> 17 | AE20: =IFERROR(INDEX($Y$2:$Y$253,MATCH(ROWS($AD20:AD$2),$AD$2:$AD$253,0)),"") -> Bermuda
B21: 2.3 | C21: Nurses not further defined | X21: =X22+1 -> 2014 | Y21: Benin | Z21: DzAOqCf0ots | AA21: BEN | AB21: AFR | AC21: =--ISNUMBER(IFERROR(SEARCH($V$1,Y21,1),"")) -> 1 | AD21: =IF(AC21=1,COUNTIF($AC21:AC$2,1),"") -> 18 | AE21: =IFERROR(INDEX($Y$2:$Y$253,MATCH(ROWS($AD21:AD$2),$AD$2:$AD$253,0)),"") -> Bhutan
B22: 3 | C22: Midwifery personnel | D22: =IF(COUNT(D23,D24,D25)>0,SUM(D23,D24,D25),NA()) -> 277 | E22: =IF(COUNT(E23,E24,E25)>0,SUM(E23,E24,E25),NA()) -> #N/A | F22: =IF(COUNT(F23,F24,F25)>0,SUM(F23,F24,F25),NA()) -> #N/A | G22: =IF(COUNT(G23,G24,G25)>0,SUM(G23,G24,G25),NA()) -> #N/A | H22: =IF(COUNT(H23,H24,H25)>0,SUM(H23,H24,H25),NA()) -> #N/A | I22: =IF(COUNT(I23,I24,I25)>0,SUM(I23,I24,I25),NA()) -> #N/A | J22: =IF(COUNT(J23,J24,J25)>0,SUM(J23,J24,J25),NA()) -> 30 | K22: =IF(COUNT(K23,K24,K25)>0,SUM(K23,K24,K25),NA()) -> 65 | ... V22: =IF(COUNT(V23,V24,V25)>0,SUM(V23,V24,V25),NA()) -> #N/A | X22: =X23+1 -> 2013 | Y22: Bermuda | Z22: ZzoDfdWIt6z | AA22: BMU | AB22: AMR | AC22: =--ISNUMBER(IFERROR(SEARCH($V$1,Y22,1),"")) -> 1 | AD22: =IF(AC22=1,COUNTIF($AC22:AC$2,1),"") -> 19 | AE22: =IFERROR(INDEX($Y$2:$Y$253,MATCH(ROWS($AD22:AD$2),$AD$2:$AD$253,0)),"") -> Bolivia (Plurinational State of)
B23: 3.1 | C23: Midwifery Professionals | D23: 102 | J23: 0 | K23: 5 | L23: 37 | M23: 19 | N23: 46 | O23: 34 | X23: =X24+1 -> 2012 | Y23: Bhutan | Z23: JQ5qF3mRCMe | AA23: BTN | AB23: SEAR | AC23: =--ISNUMBER(IFERROR(SEARCH($V$1,Y23,1),"")) -> 1 | AD23: =IF(AC23=1,COUNTIF($AC23:AC$2,1),"") -> 20 | AE23: =IFERROR(INDEX($Y$2:$Y$253,MATCH(ROWS($AD23:AD$2),$AD$2:$AD$253,0)),"") -> Bonaire, Saint Eustatius and Saba
B24: 3.2 | C24: Midwifery Associate Professionals | D24: 175 | J24: 30 | K24: 60 | L24: 33 | M24: 45 | N24: 5 | O24: 0 | X24: =X25+1 -> 2011 | Y24: Bolivia (Plurinational State of) | Z24: cpmmPDsQ3uG | AA24: BOL | AB24: AMR | AC24: =--ISNUMBER(IFERROR(SEARCH($V$1,Y24,1),"")) -> 1 | AD24: =IF(AC24=1,COUNTIF($AC24:AC$2,1),"") -> 21 | AE24: =IFERROR(INDEX($Y$2:$Y$253,MATCH(ROWS($AD24:AD$2),$AD$2:$AD$253,0)),"") -> Bosnia and Herzegovina
B25: 3.3 | C25: Midwives not further defined | X25: =X26+1 -> 2010 | Y25: Bonaire, Saint Eustatius and Saba | Z25: wyKC2eWRH3y | AA25: BES | AB25: AMR | AC25: =--ISNUMBER(IFERROR(SEARCH($V$1,Y25,1),"")) -> 1 | AD25: =IF(AC25=1,COUNTIF($AC25:AC$2,1),"") -> 22 | AE25: =IFERROR(INDEX($Y$2:$Y$253,MATCH(ROWS($AD25:AD$2),$AD$2:$AD$253,0)),"") -> Botswana
B26: 4 | C26: Dentists | D26: 372 | J26: 3 | K26: 73 | L26: 202 | M26: 54 | N26: 24 | O26: 60 | Q26: 8 | X26: =X27+1 -> 2009 | Y26: Bosnia and Herzegovina | Z26: n8iofJiiX4T | AA26: BIH | AB26: EUR | AC26: =--ISNUMBER(IFERROR(SEARCH($V$1,Y26,1),"")) -> 1 | AD26: =IF(AC26=1,COUNTIF($AC26:AC$2,1),"") -> 23 | AE26: =IFERROR(INDEX($Y$2:$Y$253,MATCH(ROWS($AD26:AD$2),$AD$2:$AD$253,0)),"") -> Bouvet Island
B27: 5 | C27: Dental Assistants and Therapists | D27: 382 | J27: 34 | K27: 113 | L27: 165 | M27: 95 | N27: 33 | O27: 77 | X27: =X28+1 -> 2008 | Y27: Botswana | Z27: c82mDnhUQly | AA27: BWA | AB27: AFR | AC27: =--ISNUMBER(IFERROR(SEARCH($V$1,Y27,1),"")) -> 1 | AD27: =IF(AC27=1,COUNTIF($AC27:AC$2,1),"") -> 24 | AE27: =IFERROR(INDEX($Y$2:$Y$253,MATCH(ROWS($AD27:AD$2),$AD$2:$AD$253,0)),"") -> Brazil
B28: 6 | C28: Dental Prosthetic Technicians | X28: =YEAR(TODAY())-18 -> 2007 | Y28: Bouvet Island | Z28: sg5v6c9tCZ3 | AA28: BVT | AB28: NA | AC28: =--ISNUMBER(IFERROR(SEARCH($V$1,Y28,1),"")) -> 1 | AD28: =IF(AC28=1,COUNTIF($AC28:AC$2,1),"") -> 25 | AE28: =IFERROR(INDEX($Y$2:$Y$253,MATCH(ROWS($AD28:AD$2),$AD$2:$AD$253,0)),"") -> British Indian Ocean Territory
B29: 7 | C29: Pharmacists | D29: 1186 | J29: 25 | K29: 268 | L29: 640 | M29: 201 | N29: 32 | O29: 70 | Q29: 42 | Y29: Brazil | Z29: dpcvWc01CeN | AA29: BRA | AB29: AMR | AC29: =--ISNUMBER(IFERROR(SEARCH($V$1,Y29,1),"")) -> 1 | AD29: =IF(AC29=1,COUNTIF($AC29:AC$2,1),"") -> 26 | AE29: =IFERROR(INDEX($Y$2:$Y$253,MATCH(ROWS($AD29:AD$2),$AD$2:$AD$253,0)),"") -> British Virgin Islands
B30: 8 | C30: Pharmaceutical Technicians | D30: 1929 | J30: 47 | K30: 480 | L30: 1027 | M30: 240 | N30: 22 | O30: 165 | Y30: British Indian Ocean Territory | Z30: PFAtPR87fHs | AA30: IOT | AB30: NA | AC30: =--ISNUMBER(IFERROR(SEARCH($V$1,Y30,1),"")) -> 1 | AD30: =IF(AC30=1,COUNTIF($AC30:AC$2,1),"") -> 27 | AE30: =IFERROR(INDEX($Y$2:$Y$253,MATCH(ROWS($AD30:AD$2),$AD$2:$AD$253,0)),"") -> Brunei Darussalam
B31: 9 | C31: Paramedical Practitioners | D31: 7984 | J31: 61 | K31: 2076 | L31: 4060 | M31: 1361 | N31: 323 | O31: 640 | Y31: British Virgin Islands | Z31: u7H4MyT2Y0A | AA31: VGB | AB31: AMR | AC31: =--ISNUMBER(IFERROR(SEARCH($V$1,Y31,1),"")) -> 1 | AD31: =IF(AC31=1,COUNTIF($AC31:AC$2,1),"") -> 28 | AE31: =IFERROR(INDEX($Y$2:$Y$253,MATCH(ROWS($AD31:AD$2),$AD$2:$AD$253,0)),"") -> Bulgaria
B32: 10 | C32: Medical and Pathology Laboratory scientists | Q32: 9 | Y32: Brunei Darussalam | Z32: MJEntShoQVK | AA32: BRN | AB32: WPR | AC32: =--ISNUMBER(IFERROR(SEARCH($V$1,Y32,1),"")) -> 1 | AD32: =IF(AC32=1,COUNTIF($AC32:AC$2,1),"") -> 29 | AE32: =IFERROR(INDEX($Y$2:$Y$253,MATCH(ROWS($AD32:AD$2),$AD$2:$AD$253,0)),"") -> Burkina Faso
B33: 11 | C33: Medical Imaging and Therapeutic Equipment Technicians | D33: 836 | J33: 10 | K33: 351 | L33: 234 | M33: 133 | N33: 29 | O33: 26 | Q33: 5 | Y33: Bulgaria | Z33: AjeCGGb8H76 | AA33: BGR | AB33: EUR | AC33: =--ISNUMBER(IFERROR(SEARCH($V$1,Y33,1),"")) -> 1 | AD33: =IF(AC33=1,COUNTIF($AC33:AC$2,1),"") -> 30 | AE33: =IFERROR(INDEX($Y$2:$Y$253,MATCH(ROWS($AD33:AD$2),$AD$2:$AD$253,0)),"") -> Burundi
B34: 12 | C34: Medical and Pathology Laboratory Technicians | D34: 5310 | J34: 40 | K34: 1176 | L34: 2024 | M34: 1297 | N34: 482 | O34: 320 | Y34: Burkina Faso | Z34: hmZE3mVAZFf | AA34: BFA | AB34: AFR | AC34: =--ISNUMBER(IFERROR(SEARCH($V$1,Y34,1),"")) -> 1 | AD34: =IF(AC34=1,COUNTIF($AC34:AC$2,1),"") -> 31 | AE34: =IFERROR(INDEX($Y$2:$Y$253,MATCH(ROWS($AD34:AD$2),$AD$2:$AD$253,0)),"") -> Cabo Verde
B35: 13 | C35: Environmental and Occupational Health Professionals | D35: 5055 | J35: 73 | K35: 1052 | L35: 1349 | M35: 1588 | N35: 781 | O35: 208 | Y35: Burundi | Z35: Xz7rnovuiOx | AA35: BDI | AB35: AFR | AC35: =--ISNUMBER(IFERROR(SEARCH($V$1,Y35,1),"")) -> 1 | AD35: =IF(AC35=1,COUNTIF($AC35:AC$2,1),"") -> 32 | AE35: =IFERROR(INDEX($Y$2:$Y$253,MATCH(ROWS($AD35:AD$2),$AD$2:$AD$253,0)),"") -> Cambodia
B36: 14 | C36: Environmental and Occupational Health Inspectors/associates | Y36: Cabo Verde | Z36: bGWaeVBrOcc | AA36: CPV | AB36: AFR | AC36: =--ISNUMBER(IFERROR(SEARCH($V$1,Y36,1),"")) -> 1 | AD36: =IF(AC36=1,COUNTIF($AC36:AC$2,1),"") -> 33 | AE36: =IFERROR(INDEX($Y$2:$Y$253,MATCH(ROWS($AD36:AD$2),$AD$2:$AD$253,0)),"") -> Cameroon
B37: 15 | C37: Traditional and Complementary Medicine Professionals | Y37: Cambodia | Z37: dscgTvwyCw8 | AA37: KHM | AB37: WPR | AC37: =--ISNUMBER(IFERROR(SEARCH($V$1,Y37,1),"")) -> 1 | AD37: =IF(AC37=1,COUNTIF($AC37:AC$2,1),"") -> 34 | AE37: =IFERROR(INDEX($Y$2:$Y$253,MATCH(ROWS($AD37:AD$2),$AD$2:$AD$253,0)),"") -> Canada
B38: 16 | C38: Traditional and Complementary Medicine Associate Professionals | Y38: Cameroon | Z38: VPesUmegQpP | AA38: CMR | AB38: AFR | AC38: =--ISNUMBER(IFERROR(SEARCH($V$1,Y38,1),"")) -> 1 | AD38: =IF(AC38=1,COUNTIF($AC38:AC$2,1),"") -> 35 | AE38: =IFERROR(INDEX($Y$2:$Y$253,MATCH(ROWS($AD38:AD$2),$AD$2:$AD$253,0)),"") -> Cayman Islands
B39: 17 | C39: Community Health Workers | D39: 6344 | J39: 193 | K39: 1232 | L39: 4032 | M39: 862 | N39: 75 | O39: 78 | Y39: Canada | Z39: AJBfDthkySs | AA39: CAN | AB39: AMR | AC39: =--ISNUMBER(IFERROR(SEARCH($V$1,Y39,1),"")) -> 1 | AD39: =IF(AC39=1,COUNTIF($AC39:AC$2,1),"") -> 36 | AE39: =IFERROR(INDEX($Y$2:$Y$253,MATCH(ROWS($AD39:AD$2),$AD$2:$AD$253,0)),"") -> Central African Republic
B40: 18 | C40: Personal care workers in health service | Y40: Cayman Islands | Z40: u3GOCB1Hu01 | AA40: CYM | AB40: AMR | AC40: =--ISNUMBER(IFERROR(SEARCH($V$1,Y40,1),"")) -> 1 | AD40: =IF(AC40=1,COUNTIF($AC40:AC$2,1),"") -> 37 | AE40: =IFERROR(INDEX($Y$2:$Y$253,MATCH(ROWS($AD40:AD$2),$AD$2:$AD$253,0)),"") -> Chad
...

Sheet DemographicsDetailed
A1: NHWA_MODULE_1_v2 | B1: NATIONAL HEALTH WORKFORCE ACCOUNTS DATA
B2: Active Health Workforce Demographic Details
B4: COUNTRY: | C4: =Demographic!C4 -> Kenya | G4: REGION: | H4: =Demographic!G4 -> AFR | M4: PERIOD: | N4: =Demographic!Q4 -> 2023
B6: SN | C6: Occupation | D6: Total | E6: Age Group
E7: Male | K7: Female
E8: < 25 yrs | F8: 25-34 yrs | G8: 35-44 yrs | H8: 45-54 yrs | I8: 55-64 yrs | J8: ≥ 65 yrs | K8: < 25 yrs | L8: 25-34 yrs | M8: 35-44 yrs | N8: 45-54 yrs | O8: 55-64 yrs | P8: ≥ 65 yrs
B9: 1 | C9: Medical Doctors | D9: =Demographic!D8 -> 4667 | E9: =IF(COUNT(E10,E11,E18)>0,SUM(E10,E11,E18),NA()) -> 25 | F9: =IF(COUNT(F10,F11,F18)>0,SUM(F10,F11,F18),NA()) -> 657 | G9: =IF(COUNT(G10,G11,G18)>0,SUM(G10,G11,G18),NA()) -> 1013 | H9: =IF(COUNT(H10,H11,H18)>0,SUM(H10,H11,H18),NA()) -> 432 | I9: =IF(COUNT(I10,I11,I18)>0,SUM(I10,I11,I18),NA()) -> 152 | J9: =IF(COUNT(J10,J11,J18)>0,SUM(J10,J11,J18),NA()) -> 53 | K9: =IF(COUNT(K10,K11,K18)>0,SUM(K10,K11,K18),NA()) -> 13 | L9: =IF(COUNT(L10,L11,L18)>0,SUM(L10,L11,L18),NA()) -> 569 | ... P9: =IF(COUNT(P10,P11,P18)>0,SUM(P10,P11,P18),NA()) -> 107
B10: 1.1 | C10: General Medical Practitioners (incl. Family medical practitioners) | D10: =Demographic!D9 -> 3015 | E10: 14 | F10: 633 | G10: 769 | H10: 219 | I10: 71 | J10: 22 | K10: 9 | L10: 543 | M10: 550 | N10: 102 | O10: 43 | P10: 69
B11: 1.2 | C11: Specialist Medical Practitioners | D11: =Demographic!D10 -> 1652 | E11: 11 | F11: 24 | G11: 244 | H11: 213 | I11: 81 | J11: 31 | K11: 4 | L11: 26 | M11: 216 | N11: 101 | O11: 57 | P11: 38
B12: 1.2.1 | C12: General paediatricians | D12: =Demographic!D11 -> 238 | E12: 1
B13: 1.2.2 | C13: Obstetricians and Gynaecologists | D13: =Demographic!D12 -> 296 | E13: 0
B14: 1.2.3 | C14: Psychiatrists Practitioners | D14: =Demographic!D13 -> 0 | E14: 0
B15: 1.2.4 | C15: Medical group of Specialists Practitioners | D15: =Demographic!D14 -> 403 | E15: 7
B16: 1.2.5 | C16: Surgical group of Specialists Practitioners | D16: =Demographic!D15 -> 479 | E16: 1
B17: 1.2.6 | C17: Other Specialists Practitioners | D17: =Demographic!D16 -> 129 | E17: 0
B18: 1.3 | C18: Medical doctors not further defined | D18: =Demographic!D17 -> 0 | E18: 0
B19: 2 | C19: Nursing Personnel | D19: =Demographic!D18 -> 34552 | E19: =IF(COUNT(E20,E21,E22)>0,SUM(E20,E21,E22),NA()) -> 496 | F19: =IF(COUNT(F20,F21,F22)>0,SUM(F20,F21,F22),NA()) -> 3228 | G19: =IF(COUNT(G20,G21,G22)>0,SUM(G20,G21,G22),NA()) -> 3863 | H19: =IF(COUNT(H20,H21,H22)>0,SUM(H20,H21,H22),NA()) -> 2190 | I19: =IF(COUNT(I20,I21,I22)>0,SUM(I20,I21,I22),NA()) -> 905 | J19: =IF(COUNT(J20,J21,J22)>0,SUM(J20,J21,J22),NA()) -> 406 | K19: =IF(COUNT(K20,K21,K22)>0,SUM(K20,K21,K22),NA()) -> 217 | L19: =IF(COUNT(L20,L21,L22)>0,SUM(L20,L21,L22),NA()) -> 6015 | ... P19: =IF(COUNT(P20,P21,P22)>0,SUM(P20,P21,P22),NA()) -> 1247
B20: 2.1 | C20: Nursing Professionals | D20: =Demographic!D19 -> 33542 | E20: 486 | F20: 3115 | G20: 3617 | H20: 2106 | I20: 862 | J20: 406 | K20: 202 | L20: 5829 | M20: 6888 | N20: 4803 | O20: 2728 | P20: 1245
B21: 2.2 | C21: Nursing Associate Professionals | D21: =Demographic!D20 -> 1010
B22: 2.3 | C22: Nurses not further defined | D22: =Demographic!D21 -> 0 | E22: 10 | F22: 113 | G22: 246 | H22: 84 | I22: 43 | J22: 0 | K22: 15 | L22: 186 | M22: 214 | N22: 184 | O22: 167 | P22: 2
B23: 3 | C23: Midwifery personnel | D23: =Demographic!D22 -> 277 | E23: =IF(COUNT(E24,E25,E26)>0,SUM(E24,E25,E26),NA()) -> 10 | F23: =IF(COUNT(F24,F25,F26)>0,SUM(F24,F25,F26),NA()) -> 1 | G23: =IF(COUNT(G24,G25,G26)>0,SUM(G24,G25,G26),NA()) -> 11 | H23: =IF(COUNT(H24,H25,H26)>0,SUM(H24,H25,H26),NA()) -> 13 | I23: =IF(COUNT(I24,I25,I26)>0,SUM(I24,I25,I26),NA()) -> 11 | J23: =IF(COUNT(J24,J25,J26)>0,SUM(J24,J25,J26),NA()) -> 5 | K23: =IF(COUNT(K24,K25,K26)>0,SUM(K24,K25,K26),NA()) -> 15 | L23: =IF(COUNT(L24,L25,L26)>0,SUM(L24,L25,L26),NA()) -> 190 | ... P23: =IF(COUNT(P24,P25,P26)>0,SUM(P24,P25,P26),NA()) -> 31
B24: 3.1 | C24: Midwifery Professionals | D24: =Demographic!D23 -> 102 | E24: 0 | F24: 1 | G24: 5 | H24: 8 | I24: 11 | J24: 5 | K24: 15 | L24: 186 | M24: 214 | N24: 184 | O24: 167 | P24: 2
B25: 3.2 | C25: Midwifery Associate Professionals | D25: =Demographic!D24 -> 175 | E25: 10 | F25: 0 | G25: 6 | H25: 5 | I25: 0 | J25: 0 | K25: 0 | L25: 4 | M25: 32 | N25: 11 | O25: 35 | P25: 29
B26: 3.3 | C26: Midwives not further defined | D26: =Demographic!D25 -> 0
B27: 4 | C27: Dentists | D27: =Demographic!D26 -> 372 | E27: 33 | F27: 57 | G27: 76 | H27: 51 | I27: 26 | J27: 22 | K27: 1 | L27: 56 | M27: 89 | N27: 44 | O27: 7 | P27: 55
B28: 5 | C28: Dental Assistants and Therapists | D28: =Demographic!D27 -> 382 | E28: 22 | F28: 126 | G28: 391 | H28: 124 | I28: 22 | J28: 26 | K28: 3 | L28: 142 | M28: 249 | N28: 77 | O28: 10 | P28: 44
B29: 6 | C29: Dental Prosthetic Technicians | D29: =Demographic!D28 -> 0
B30: 7 | C30: Pharmacists | D30: =Demographic!D29 -> 1186 | E30: 22 | F30: 126 | G30: 391 | H30: 124 | I30: 22 | J30: 26 | K30: 3 | L30: 142 | M30: 249 | N30: 77 | O30: 10 | P30: 44
B31: 8 | C31: Pharmaceutical Technicians | D31: =Demographic!D30 -> 1929 | E31: 22 | F31: 259 | G31: 568 | H31: 129 | I31: 13 | J31: 64 | K31: 25 | L31: 221 | M31: 459 | N31: 111 | O31: 9 | P31: 101
B32: 9 | C32: Paramedical Practitioners | D32: =Demographic!D31 -> 7984 | E32: 30 | F32: 1024 | G32: 2215 | H32: 792 | I32: 196 | J32: 289 | K32: 31 | L32: 1052 | M32: 1845 | N32: 569 | O32: 127 | P32: 351
B33: 10 | C33: Medical and Pathology Laboratory scientists | D33: =Demographic!D32 -> 0 | E33: 18 | F33: 609 | G33: 1088 | H33: 693 | I33: 282 | J33: 155 | K33: 22 | L33: 567 | M33: 936 | N33: 604 | O33: 200 | P33: 165
B34: 11 | C34: Medical Imaging and Therapeutic Equipment Technicians | D34: =Demographic!D33 -> 836 | E34: 4 | F34: 222 | G34: 142 | H34: 89 | I34: 21 | J34: 14 | K34: 6 | L34: 129 | M34: 92 | N34: 44 | O34: 8 | P34: 12
B35: 12 | C35: Medical and Pathology Laboratory Technicians | D35: =Demographic!D34 -> 5310
B36: 13 | C36: Environmental and Occupational Health Professionals | D36: =Demographic!D35 -> 5055
B37: 14 | C37: Environmental and Occupational Health Inspectors/associates | D37: =Demographic!D36 -> 0 | E37: 34 | F37: 540 | G37: 730 | H37: 971 | I37: 523 | J37: 98 | K37: 39 | L37: 512 | M37: 619 | N37: 617 | O37: 258 | P37: 110
B38: 15 | C38: Traditional and Complementary Medicine Professionals | D38: =Demographic!D37 -> 0
B39: 16 | C39: Traditional and Complementary Medicine Associate Professionals | D39: =Demographic!D38 -> 0
B40: 17 | C40: Community Health Workers | D40: =Demographic!D39 -> 6344 | E40: 103 | F40: 465 | G40: 1882 | H40: 335 | I40: 43 | J40: 26 | K40: 90 | L40: 767 | M40: 2150 | N40: 527 | O40: 32 | P40: 52
B41: 18 | C41: Personal care workers in health service | D41: =Demographic!D40 -> 0
B42: 18.1 | C42: Health Care Assistants | D42: =Demographic!D41 -> 0
...

Sheet CountryOfTraining
B1: NATIONAL HEALTH WORKFORCE ACCOUNTS DATA
B2: Country of training for foreign trained staff | Q2: =Demographic!W2 -> #N/A
B4: COUNTRY: | C4: =Demographic!C4 -> Kenya | E4: REGION: | F4: =Demographic!G4 -> AFR | N4: PERIOD: | O4: =Demographic!Q4 -> 2023
B7: SN | C7: Country | D7: Medical Doctors | E7: Nurses | F7: Midwives | G7: Dentists | H7: Pharmacists
B8: 1 | C8: Afghanistan
B9: 2 | C9: Albania
B10: 3 | C10: Algeria
B11: 4 | C11: Andorra
B12: 5 | C12: Angola
B13: 6 | C13: Antigua and Barbuda
B14: 7 | C14: Argentina
B15: 8 | C15: Armenia
B16: 9 | C16: Australia
B17: 10 | C17: Austria
B18: 11 | C18: Azerbaijan
B19: 12 | C19: Bahamas
... B202: 195 | C202: Other country (ies)

Sheet FacilityOwnershipAndFacility
B1: NATIONAL HEALTH WORKFORCE ACCOUNTS DATA
B2: Facility ownership and facility type
B4: COUNTRY: | C4: =Demographic!C4 -> Kenya | F4: REGION: | G4: =Demographic!G4 -> AFR | L4: PERIOD: | M4: =Demographic!Q4 -> 2023
B9: SN | C9: Occupation | D9: Total | E9: Ownership | H9: Working Facility Type
E10: Public | F10: Private not for profit | G10: Private for profit | H10: Hospitals | I10: Residential long-term care facilities | J10: Providers of ambulatory health care | K10: Ancillary services | L10: Retailers | M10: Providers of preventive care
B11: 1 | C11: Medical Doctors | D11: =Demographic!D8 -> 4667 | E11: =IF(COUNT(E12,E13,E20)>0,SUM(E12,E13,E20),NA()) -> 4747 | F11: =IF(COUNT(F12,F13,F20)>0,SUM(F12,F13,F20),NA()) -> #N/A | G11: =IF(COUNT(G12,G13,G20)>0,SUM(G12,G13,G20),NA()) -> #N/A | H11: =IF(COUNT(H12,H13,H20)>0,SUM(H12,H13,H20),NA()) -> 4102 | I11: =IF(COUNT(I12,I13,I20)>0,SUM(I12,I13,I20),NA()) -> #N/A | J11: =IF(COUNT(J12,J13,J20)>0,SUM(J12,J13,J20),NA()) -> #N/A | K11: =IF(COUNT(K12,K13,K20)>0,SUM(K12,K13,K20),NA()) -> #N/A | L11: =IF(COUNT(L12,L13,L20)>0,SUM(L12,L13,L20),NA()) -> #N/A | M11: =IF(COUNT(M12,M13,M20)>0,SUM(M12,M13,M20),NA()) -> #N/A
B12: 1.1 | C12: General Medical Practitioners (incl. Family medical practitioners) | D12: =Demographic!D9 -> 3015 | E12: 3076 | H12: 2697
B13: 1.2 | C13: Specialist Medical Practitioners | D13: =Demographic!D10 -> 1652 | E13: 1671 | H13: 1405
B14: 1.2.1 | C14: General paediatricians | D14: =Demographic!D11 -> 238 | E14: 238 | H14: 227
B15: 1.2.2 | C15: Obstetricians and Gynaecologists | D15: =Demographic!D12 -> 296 | E15: 296 | H15: 278
B16: 1.2.3 | C16: Psychiatrists Practitioners | D16: =Demographic!D13 -> 0
B17: 1.2.4 | C17: Medical group of Specialists Practitioners | D17: =Demographic!D14 -> 403 | E17: 403 | H17: 358
B18: 1.2.5 | C18: Surgical group of Specialists Practitioners | D18: =Demographic!D15 -> 479 | E18: 479 | H18: 428
B19: 1.2.6 | C19: Other Specialists Practitioners | D19: =Demographic!D16 -> 129 | E19: 129 | H19: 120
B20: 1.3 | C20: Medical doctors not further defined | D20: =Demographic!D17 -> 0
B21: 2 | C21: Nursing Personnel | D21: =Demographic!D18 -> 34552 | E21: =IF(COUNT(E22,E23,E24)>0,SUM(E22,E23,E24),NA()) -> 34127 | F21: =IF(COUNT(F22,F23,F24)>0,SUM(F22,F23,F24),NA()) -> #N/A | G21: =IF(COUNT(G22,G23,G24)>0,SUM(G22,G23,G24),NA()) -> #N/A | H21: =IF(COUNT(H22,H23,H24)>0,SUM(H22,H23,H24),NA()) -> 17914 | I21: =IF(COUNT(I22,I23,I24)>0,SUM(I22,I23,I24),NA()) -> #N/A | J21: =IF(COUNT(J22,J23,J24)>0,SUM(J22,J23,J24),NA()) -> #N/A | K21: =IF(COUNT(K22,K23,K24)>0,SUM(K22,K23,K24),NA()) -> #N/A | L21: =IF(COUNT(L22,L23,L24)>0,SUM(L22,L23,L24),NA()) -> #N/A | M21: =IF(COUNT(M22,M23,M24)>0,SUM(M22,M23,M24),NA()) -> #N/A
B22: 2.1 | C22: Nursing Professionals | D22: =Demographic!D19 -> 33542 | E22: 34127 | H22: 17914
B23: 2.2 | C23: Nursing Associate Professionals | D23: =Demographic!D20 -> 1010
B24: 2.3 | C24: Nurses not further defined | D24: =Demographic!D21 -> 0
B25: 3 | C25: Midwifery personnel | D25: =Demographic!D22 -> 277 | E25: =IF(COUNT(E26,E27,E28)>0,SUM(E26,E27,E28),NA()) -> 277 | F25: =IF(COUNT(F26,F27,F28)>0,SUM(F26,F27,F28),NA()) -> #N/A | G25: =IF(COUNT(G26,G27,G28)>0,SUM(G26,G27,G28),NA()) -> #N/A | H25: =IF(COUNT(H26,H27,H28)>0,SUM(H26,H27,H28),NA()) -> 305 | I25: =IF(COUNT(I26,I27,I28)>0,SUM(I26,I27,I28),NA()) -> #N/A | J25: =IF(COUNT(J26,J27,J28)>0,SUM(J26,J27,J28),NA()) -> #N/A | K25: =IF(COUNT(K26,K27,K28)>0,SUM(K26,K27,K28),NA()) -> #N/A | L25: =IF(COUNT(L26,L27,L28)>0,SUM(L26,L27,L28),NA()) -> #N/A | M25: =IF(COUNT(M26,M27,M28)>0,SUM(M26,M27,M28),NA()) -> #N/A
B26: 3.1 | C26: Midwifery Professionals | D26: =Demographic!D23 -> 102 | E26: 102 | H26: 115
B27: 3.2 | C27: Midwifery Associate Professionals | D27: =Demographic!D24 -> 175 | E27: 175 | H27: 190
B28: 3.3 | C28: Midwives not further defined | D28: =Demographic!D25 -> 0
B29: 4 | C29: Dentists | D29: =Demographic!D26 -> 372 | E29: 374 | H29: 364
B30: 5 | C30: Dental Assistants and Therapists | D30: =Demographic!D27 -> 382 | E30: 389 | H30: 292
B31: 6 | C31: Dental Prosthetic Technicians | D31: =Demographic!D28 -> 0
B32: 7 | C32: Pharmacists | D32: =Demographic!D29 -> 1186 | E32: 1206 | H32: 1031
B33: 8 | C33: Pharmaceutical Technicians | D33: =Demographic!D30 -> 1929 | E33: 1977 | H33: 1269
B34: 9 | C34: Paramedical Practitioners | D34: =Demographic!D31 -> 7984 | E34: 8180 | H34: 4938
B35: 10 | C35: Medical and Pathology Laboratory scientists | D35: =Demographic!D32 -> 0 | E35: 5442 | H35: 3092
B36: 11 | C36: Medical Imaging and Therapeutic Equipment Technicians | D36: =Demographic!D33 -> 836 | E36: 848
B37: 12 | C37: Medical and Pathology Laboratory Technicians | D37: =Demographic!D34 -> 5310
B38: 13 | C38: Environmental and Occupational Health Professionals | D38: =Demographic!D35 -> 5055 | E38: 5144 | H38: 2025
B39: 14 | C39: Environmental and Occupational Health Inspectors/associates | D39: =Demographic!D36 -> 0
B40: 15 | C40: Traditional and Complementary Medicine Professionals | D40: =Demographic!D37 -> 0
B41: 16 | C41: Traditional and Complementary Medicine Associate Professionals | D41: =Demographic!D38 -> 0
B42: 17 | C42: Community Health Workers | D42: =Demographic!D39 -> 6344 | E42: 6344 | H42: 1026
B43: 18 | C43: Personal care workers in health service | D43: =Demographic!D40 -> 0
B44: 18.1 | C44: Health Care Assistants | D44: =Demographic!D41 -> 0
B45: 18.2 | C45: Home-based Personal Care | D45: =Demographic!D42 -> 0
...

Sheet Inflows&Outflows
B1: NATIONAL HEALTH WORKFORCE ACCOUNTS DATA
B2: Inflows & Outflows | T2: =Demographic!W2 -> #N/A
B4: COUNTRY: | C4: =Demographic!C4 -> Kenya | E4: REGION: | F4: =Demographic!G4 -> AFR | K4: PERIOD: | L4: =Demographic!Q4 -> 2023
D7: Newly active Health Workers | E7: Newly active domestic trained HWF | H7: Newly active foreign trained employed | K7: Number of exits | L7: Voluntary exits | O7: Involuntary exits | R7: Vacancy rate
D8: Total | E8: Total | F8: Male | G8: Female | H8: Total | I8: Male | J8: Female | K8: Total | L8: Total | M8: Male | N8: Female | O8: Total | P8: Male | Q8: Female | R8: Vacant posts | S8: Total posts
B9: 1 | C9: Medical Doctors
B10: 1.1 | C10: General Medical Practitioners
B11: 1.2 | C11: Specialist Medical Practitioners
B12: 2 | C12: Nursing Personnel
B13: 3 | C13: Midwifery personnel
B14: 4 | C14: Dentist
B15: 5 | C15: Pharmacist

Sheet SourceType
B1: NATIONAL HEALTH WORKFORCE ACCOUNTS DATA
B2: Source Type
B4: COUNTRY: | C4: =Demographic!C4 -> Kenya | E4: REGION: | F4: =Demographic!G4 -> AFR | H4: PERIOD: | I4: =Demographic!Q4 -> 2023
B6: SN | C6: Occupation | D6: Source Type
A7: pSRNRBuOBi8 | B7: 1 | C7: Medical Doctors | D7: Ministry of Health
A8: idY7moseTTD | B8: 1.1 | C8: General Medical Practitioners (incl. Family medical practitioners) | D8: Ministry of Health
A9: RfqYbGs8Za9 | B9: 1.2 | C9: Specialist Medical Practitioners | D9: Ministry of Health
A10: nS0ZJGJUX0u | B10: 1.2.1 | C10: General paediatricians | D10: Ministry of Health
A11: bSvvw3Ms4BE | B11: 1.2.2 | C11: Obstetricians and Gynaecologists | D11: Ministry of Health
A12: h3kClMEpMAy | B12: 1.2.3 | C12: Psychiatrists Practitioners | D12: Ministry of Health
A13: e3ba55rLVTZ | B13: 1.2.4 | C13: Medical group of Specialists Practitioners | D13: Ministry of Health
A14: KAU5IPKoIgx | B14: 1.2.5 | C14: Surgical group of Specialists Practitioners | D14: Ministry of Health
A15: bYXQMVmauLD | B15: 1.2.6 | C15: Other Specialists Practitioners
A16: MFUxfSaYW2e | B16: 1.3 | C16: Medical doctors not further defined
A17: dutH7uvTAut | B17: 2 | C17: Nursing Personnel | D17: Ministry of Health
A18: vtidz1k9BOw | B18: 2.1 | C18: Nursing Professionals | D18: Ministry of Health
A19: ud6YiQ9ekgi | B19: 2.2 | C19: Nursing Associate Professionals | D19: Ministry of Health
A20: P5RXZZXrLGM | B20: 2.3 | C20: Nurses not further defined
A21: ON8DBreBXlt | B21: 3 | C21: Midwifery personnel | D21: Ministry of Health
A22: SRSiY1qW6W8 | B22: 3.1 | C22: Midwifery Professionals
A23: M1hZV0c1jpw | B23: 3.2 | C23: Midwifery Associate Professionals
A24: Va9QjeOhGZa | B24: 3.3 | C24: Midwives not further defined
A25: E6yC5xp14iQ | B25: 4 | C25: Dentists | D25: Ministry of Health
A26: zmJu31AVVts | B26: 5 | C26: Dental Assistants and Therapists | D26: Ministry of Health
A27: HmC6k52OuR4 | B27: 6 | C27: Dental Prosthetic Technicians | D27: Ministry of Health
A28: eP4EDcfclsH | B28: 7 | C28: Pharmacists | D28: Ministry of Health
A29: cnxVb8H17tm | B29: 8 | C29: Pharmaceutical Technicians | D29: Ministry of Health
A30: mnfnutsHsxh | B30: 9 | C30: Paramedical Practitioners | D30: Ministry of Health
A31: hiSNbC7WWAb | B31: 10 | C31: Medical and Pathology Laboratory scientists | D31: Ministry of Health
A32: PXZbVlkKwcw | B32: 11 | C32: Medical Imaging and Therapeutic Equipment Technicians | D32: Ministry of Health
A33: TcSxFdjVWEh | B33: 12 | C33: Medical and Pathology Laboratory Technicians | D33: Ministry of Health
A34: ZtjIuqdv5S7 | B34: 13 | C34: Environmental and Occupational Health Professionals | D34: Ministry of Health
A35: BgJoMJEnaO1 | B35: 14 | C35: Environmental and Occupational Health Inspectors/associates | D35: Ministry of Health
A36: LO5oNfvohPx | B36: 15 | C36: Traditional and Complementary Medicine Professionals
A37: uQe1J0rpnwS | B37: 16 | C37: Traditional and Complementary Medicine Associate Professionals
A38: XIHIwocWj9J | B38: 17 | C38: Community Health Workers | D38: Ministry of Health
A39: RK9mngtJtTL | B39: 18 | C39: Personal care workers in health service
A40: D2MFGJKtc1Y | B40: 18.1 | C40: Health Care Assistants
A41: m4eOcU1zHtL | B41: 18.2 | C41: Home-based Personal Care
A42: VZnZ8xJoaIW | B42: 18.3 | C42: Personal care workers in health service n.e.c
...

Sheet TypeOfContract
B1: NATIONAL HEALTH WORKFORCE ACCOUNTS DATA
B2: Facility ownership and facility type
B4: COUNTRY: | C4: =Demographic!C4 -> Kenya | E4: REGION: | F4: =Demographic!G4 -> AFR | I4: PERIOD: | J4: =Demographic!Q4 -> 2023
B9: SN | C9: Occupation | D9: Total | E9: Contract Type
E10: Full-time contract | F10: Part-time contract
B11: 1 | C11: Medical Doctors | D11: =Demographic!D8 -> 4667 | E11: =IF(COUNT(E12,E13,E20)>0,SUM(E12,E13,E20),NA()) -> 4747 | F11: =IF(COUNT(F12,F13,F20)>0,SUM(F12,F13,F20),NA()) -> #N/A
B12: 1.1 | C12: General Medical Practitioners (incl. Family medical practitioners) | D12: =Demographic!D9 -> 3015 | E12: 3076
B13: 1.2 | C13: Specialist Medical Practitioners | D13: =Demographic!D10 -> 1652 | E13: 1671
B14: 1.2.1 | C14: General paediatricians | D14: =Demographic!D11 -> 238 | E14: 238
B15: 1.2.2 | C15: Obstetricians and Gynaecologists | D15: =Demographic!D12 -> 296 | E15: 296
B16: 1.2.3 | C16: Psychiatrists Practitioners | D16: =Demographic!D13 -> 0
B17: 1.2.4 | C17: Medical group of Specialists Practitioners | D17: =Demographic!D14 -> 403 | E17: 403
B18: 1.2.5 | C18: Surgical group of Specialists Practitioners | D18: =Demographic!D15 -> 479 | E18: 479
B19: 1.2.6 | C19: Other Specialists Practitioners | D19: =Demographic!D16 -> 129 | E19: 129
B20: 1.3 | C20: Medical doctors not further defined | D20: =Demographic!D17 -> 0
B21: 2 | C21: Nursing Personnel | D21: =Demographic!D18 -> 34552 | E21: =IF(COUNT(E22,E23,E24)>0,SUM(E22,E23,E24),NA()) -> 34127 | F21: =IF(COUNT(F22,F23,F24)>0,SUM(F22,F23,F24),NA()) -> #N/A
B22: 2.1 | C22: Nursing Professionals | D22: =Demographic!D19 -> 33542 | E22: 34127
B23: 2.2 | C23: Nursing Associate Professionals | D23: =Demographic!D20 -> 1010
B24: 2.3 | C24: Nurses not further defined | D24: =Demographic!D21 -> 0
B25: 3 | C25: Midwifery personnel | D25: =Demographic!D22 -> 277 | E25: =IF(COUNT(E26,E27,E28)>0,SUM(E26,E27,E28),NA()) -> 277 | F25: =IF(COUNT(F26,F27,F28)>0,SUM(F26,F27,F28),NA()) -> #N/A
B26: 3.1 | C26: Midwifery Professionals | D26: =Demographic!D23 -> 102 | E26: 102
B27: 3.2 | C27: Midwifery Associate Professionals | D27: =Demographic!D24 -> 175 | E27: 175
B28: 3.3 | C28: Midwives not further defined | D28: =Demographic!D25 -> 0
B29: 4 | C29: Dentists | D29: =Demographic!D26 -> 372 | E29: 374
B30: 5 | C30: Dental Assistants and Therapists | D30: =Demographic!D27 -> 382 | E30: 389
B31: 6 | C31: Dental Prosthetic Technicians | D31: =Demographic!D28 -> 0
B32: 7 | C32: Pharmacists | D32: =Demographic!D29 -> 1186 | E32: 1206
B33: 8 | C33: Pharmaceutical Technicians | D33: =Demographic!D30 -> 1929 | E33: 1977
B34: 9 | C34: Paramedical Practitioners | D34: =Demographic!D31 -> 7984 | E34: 8180
B35: 10 | C35: Medical and Pathology Laboratory scientists | D35: =Demographic!D32 -> 0 | E35: 5442
B36: 11 | C36: Medical Imaging and Therapeutic Equipment Technicians | D36: =Demographic!D33 -> 836 | E36: 848
B37: 12 | C37: Medical and Pathology Laboratory Technicians | D37: =Demographic!D34 -> 5310
B38: 13 | C38: Environmental and Occupational Health Professionals | D38: =Demographic!D35 -> 5055 | E38: 5144
B39: 14 | C39: Environmental and Occupational Health Inspectors/associates | D39: =Demographic!D36 -> 0
B40: 15 | C40: Traditional and Complementary Medicine Professionals | D40: =Demographic!D37 -> 0
B41: 16 | C41: Traditional and Complementary Medicine Associate Professionals | D41: =Demographic!D38 -> 0
B42: 17 | C42: Community Health Workers | D42: =Demographic!D39 -> 6344 | E42: 6344
B43: 18 | C43: Personal care workers in health service | D43: =Demographic!D40 -> 0
B44: 18.1 | C44: Health Care Assistants | D44: =Demographic!D41 -> 0
B45: 18.2 | C45: Home-based Personal Care | D45: =Demographic!D42 -> 0
...

Sheet Validation
A1: =_uc8uSqVVt4n -> NHWA Module 1 (2023)
A2: Organisation Units | B2: Periods | C2: Options | D2: Boolean | E2: True only
A3: =_oofyLUJJ6Vy -> Afghanistan | B3: 2019 | C3: =_Xr12mI7VPn3 -> default | D3: =_true -> ☒ | E3: =_true -> ☒
A4: =_VGOzFKfSazN -> Albania | D4: =_false -> ☐
A5: =_mNa42CHbkO7 -> Algeria
A6: =_VYVKdqiXo4b -> American Samoa
A7: =_Rmy6DbwekE1 -> Andorra
A8: =_jFOZHDZpjPL -> Angola
A9: =_f4ZFD2aswys -> Anguilla
A10: =_pfhvgmllA9M -> Antigua and Barbuda
A11: =_AZdPnw0b1lm -> Argentina
A12: =_cWrL45je7mw -> Armenia
A13: =_lKZR6UK0afN -> Aruba
A14: =_LbWpsX1FJcC -> Australia
A15: =_e9IoKRAkYLO -> Austria
A16: =_ST86paYjRHP -> Azerbaijan
A17: =_VbbSe7wgS9s -> Bahamas
A18: =_T7tKHiW1Db1 -> Bahrain
A19: =_dNLjKwsVjod -> Bangladesh
A20: =_iNT35p3jsEM -> Barbados
A21: =_Tr4i6jeDDqj -> Belarus
A22: =_KwgjnBBpe5b -> Belgium
A23: =_Nrnay4JA8Ga -> Belize
A24: =_DzAOqCf0ots -> Benin
A25: =_ZzoDfdWIt6z -> Bermuda
A26: =_JQ5qF3mRCMe -> Bhutan
A27: =_cpmmPDsQ3uG -> Bolivia (Plurinational State of)
A28: =_wyKC2eWRH3y -> Bonaire, Saint Eustatius and Saba
A29: =_n8iofJiiX4T -> Bosnia and Herzegovina
A30: =_c82mDnhUQly -> Botswana
A31: =_sg5v6c9tCZ3 -> Bouvet Island
A32: =_dpcvWc01CeN -> Brazil
A33: =_PFAtPR87fHs -> British Indian Ocean Territory
A34: =_u7H4MyT2Y0A -> British Virgin Islands
A35: =_MJEntShoQVK -> Brunei Darussalam
A36: =_AjeCGGb8H76 -> Bulgaria
A37: =_hmZE3mVAZFf -> Burkina Faso
A38: =_Xz7rnovuiOx -> Burundi
A39: =_bGWaeVBrOcc -> Cabo Verde
A40: =_dscgTvwyCw8 -> Cambodia
...

Sheet Metadata
A1: Identifier | B1: Type | C1: Name | D1: Value Type | E1: Option Set | F1: Possible Values
A3: cDnBDmJhson | B3: dataElements | C3: Other Specialists Practitioners Stock HF owner | D3: INTEGER_ZERO_OR_POSITIVE
A4: zWqYNMlrEgt | B4: dataElements | C4: Medical Laboratory Technicians Stock By Level | D4: INTEGER_ZERO_OR_POSITIVE
A5: tkCXuIKxKvK | B5: dataElements | C5: Audiologists and Speech Therapists Stock By Age | D5: INTEGER_ZERO_OR_POSITIVE
A6: rjQiZlCjHp6 | B6: dataElements | C6: Specialist Medical Practitioners Stock By Level | D6: INTEGER_ZERO_OR_POSITIVE
A7: oNyG3X3DPbz | B7: dataElements | C7: Nursing Professionals Stock birth loc. | D7: INTEGER_ZERO_OR_POSITIVE
A8: C7jmannlc7B | B8: dataElements | C8: Community Health Workers Stock birth loc. | D8: INTEGER_ZERO_OR_POSITIVE
A9: HmC6k52OuR4 | B9: dataElements | C9: Medical Imaging Technicians composition source typ | D9: TRUE_ONLY
A10: e0qvyzapmu3 | B10: dataElements | C10: Other Specialists Practitioners Stock traing loc. | D10: INTEGER_ZERO_OR_POSITIVE
A11: Qf4UX9h7VHw | B11: dataElements | C11: Imaging Technicians Stock By Sex | D11: INTEGER_ZERO_OR_POSITIVE
A12: lguPmuZBWDk | B12: dataElements | C12: Midwifery Professionals Stock HF type | D12: INTEGER_ZERO_OR_POSITIVE
A13: Ls5uiJRlx9L | B13: dataElements | C13: Engineering staff composition source type | D13: TRUE_ONLY
A14: eEQkLvHHoSU | B14: dataElements | C14: Nursing Associate Professionals Stock Total | D14: INTEGER_ZERO_OR_POSITIVE
... A548: JBCKANhdTX4 | B548: dataElements | C548: Home-based Personal Care Workers Stock birth loc. | D548: INTEGER_ZERO_OR_POSITIVE
A549: b4XQdI8eqUZ | B549: categoryCombos | C549: NHWA_Age Group (<25,25-34,35-44,45-54,55-64,>65) yrs
A550: ihsAfRE2H0G | B550: categoryCombos | C550: NHWA_Activity Level
A551: swjTZ93dg4h | B551: categoryCombos | C551: NHWA_HF Ownership
A552: pTF4zHINsQO | B552: categoryCombos | C552: NHWA_Place of Training
A553: wywD4cOewZX | B553: categoryCombos | C553: NHWA_Source Type Mod 1
A554: U5QaBXGsFlJ | B554: categoryCombos | C554: NHWA_Working Facility Type
A555: A5bhyAmcZKV | B555: categoryCombos | C555: NHWA_Place of Birth
A556: uAB8kfk7I3z | B556: categoryCombos | C556: NHWA_Sex
A557: sPP5gqI4TC8 | B557: categoryCombos | C557: NHWA_Foreing Trained HWF
A558: JzvGfLYkX17 | B558: categoryCombos | C558: default
A559: vFHz3MkTm0K | B559: categories | C559: NHWA_Working Facility Type
A560: o2PYOw8PSBa | B560: categories | C560: NHWA_Sex
... A1305: false | B1305: boolean | C1305: ☐
